Workbook
Name _Fill: #REF!
Name _Sort: #REF!
Name _Key1: #REF!
Name _Key2: #REF!

Sheet Summary_detail
B1: Summary Detail
M2: GWP
F3: Unit: Tonnes | K3: Unit: Tonnes CO2e | M3: 28 | N3: 273
B4: Categories | C4: A | D4: B | E4: C | F4: D | H4: A | I4: B | J4: C | K4: D
C5: CO2 Emissions | D5: CH4 Emissions | E5: N2O Emissions | F5: Total Emissions | H5: CO2 Emissions | I5: CH4 Emissions | J5: N2O Emissions | K5: Total Emissions | L5: Total %
C6: tonnes CO2 | D6: tonnes CH4 | E6: tonnes N2O | F6: tonnes CO2e | H6: tonnes CO2e
F7: D = A+B*28+C*273 | K7: D = A+B+C
C8: =SUM(C9,C15) -> 7298224.4 | D8: =SUM(D9,D15) -> 76.014515 | E8: =SUM(E9,E15) -> 113.73233 | F8: =F9+F15 -> 7331401.8 | H8: =C8 -> 7298224.4 | I8: =D8*$M$3 -> 2128.4064 | J8: =E8*$N$3 -> 31048.927 | K8: =SUM(H8:J8) -> 7331401.8 | L8: 1
B9: Scope 1 | C9: =SUM(C10:C14) -> 7293545.6 | D9: =SUM(D10:D14) -> 76.014515 | E9: =SUM(E10:E14) -> 113.73233 | F9: =SUM(F10:F14) -> 7326723 | H9: =C9 -> 7293545.6 | I9: =D9*$M$3 -> 2128.4064 | J9: =E9*$N$3 -> 31048.927 | K9: =SUM(H9:J9) -> 7326723 | L9: =F9/$F$8 -> 0.99936181
B10: S1-Stationary Combustion | C10: ='S1-Stationary Combustion'!U67 -> 7287186.1 | D10: ='S1-Stationary Combustion'!W67 -> 75.986278 | E10: ='S1-Stationary Combustion'!Y67 -> 113.70454 | F10: =C10+D10*28+E10*273 -> 7320355 | H10: =C10 -> 7287186.1 | I10: =D10*$M$3 -> 2127.6158 | J10: =E10*$N$3 -> 31041.34 | K10: =SUM(H10:J10) -> 7320355 | L10: =F10/$F$8 -> 0.99849323
B11: S1-Mobile Combustion | C11: ='S1-Mobile Combustion'!U67 -> 528.11355 | D11: ='S1-Mobile Combustion'!W67 -> 0.028237466 | E11: ='S1-Mobile Combustion'!Y67 -> 0.027788713 | F11: =C11+D11*28+E11*273 -> 536.49051 | H11: =C11 -> 528.11355 | I11: =D11*$M$3 -> 0.79064904 | J11: =E11*$N$3 -> 7.5863186 | K11: =SUM(H11:J11) -> 536.49051 | L11: =F11/$F$8 -> 7.3177072e-05
B12: S1-Refrigerants | C12: ='S1-Refrigerants'!S10 -> 642.04794 | F12: =C12+D12*28+E12*273 -> 642.04794 | H12: =C12 -> 642.04794 | K12: =SUM(H12:J12) -> 642.04794 | L12: =F12/$F$8 -> 8.7575058e-05
B13: S1-Industrial processes | C13: ='S1-Industrial processes'!R18 -> 5122.0367 | F13: =C13+D13*28+E13*273 -> 5122.0367 | H13: =C13 -> 5122.0367 | K13: =SUM(H13:J13) -> 5122.0367 | L13: =F13/$F$8 -> 0.00069864357
B14: S1-Wastewater Treatment | C14: =SUM('S1-Wastewater Treatment'!Y13,'S1-Wastewater Treatment'!Y25) -> 67.342351 | F14: =C14+D14*28+E14*273 -> 67.342351 | H14: =C14 -> 67.342351 | K14: =SUM(H14:J14) -> 67.342351 | L14: =F14/$F$8 -> 9.1854672e-06
B15: Scope 2 | C15: =C16 -> 4678.8117 | F15: =C15 -> 4678.8117 | H15: =C15 -> 4678.8117 | K15: =SUM(H15:J15) -> 4678.8117 | L15: =F15/$F$8 -> 0.00063818788
B16: S2-Electricity Consumption | C16: ='S2-Electricity Consumption'!F19 -> 4678.8117 | F16: =C16 -> 4678.8117 | H16: =C16 -> 4678.8117 | K16: =SUM(H16:J16) -> 4678.8117 | L16: =F16/$F$8 -> 0.00063818788
B22: S1-Stationary Combustion | C22: =L10 -> 0.99849323
B23: S1-Mobile Combustion | C23: =L11 -> 7.3177072e-05
B24: S1-Refrigerants | C24: =L12 -> 8.7575058e-05
B25: S1-Industrial processes | C25: =L13 -> 0.00069864357
B26: S1-Wastewater Treatment | C26: =L14 -> 9.1854672e-06
B27: S2-Electricity Consumption | C27: =L16 -> 0.00063818788

Sheet Conversion Factors
B1: Conversion factor
B3: Conversion factor of fuel types from liters, m3,… =>> tons | J3: GWP* (AR6) | N3: Maximum methane generation potential (Bo) | R3: Default MCF values for domestic wastewater
B4: No. | C4: Type Fuel | D4: Unit | E4: Parameter | F4: Select | G4: Source | H4: Note | J4: Name | K4: Chemical formula | L4: GWP* (AR6) | N4: Treatment measures | O4: Describe | P4: Bo | S4: CH4 | T4: MCF
B5: 1 | C5: Diesel Oil | D5: tons/m3 | E5: 0,82-0,86 | F5: 0.86 | G5: TCVN 5689:2013 | J5: Carbon dioxide | K5: CO2 | L5: 1 | N5: Domestic wastewater | O5: kgCH4/kgBOD | P5: 0.6 | R5: Methane conversion factor of aerobic and concentrated wastewater treatment system | S5: CH4 | T5: 0.3
B6: 2 | C6: Other Kerosene | D6: Liter | J6: Methane | K6: CH4 | L6: 27.9 | N6: Industrial wastewater | O6: kgCH4/kgCOD | P6: 0.25 | R6: Methane conversion factor of septic system | S6: CH4 | T6: 0.5
B7: 3 | C7: Gasoline | D7: kg/Liter | F7: 0.8 | H7: 15 degrees Celsius | J7: Nitrous oxide | K7: N2O | L7: 273 | R7: Methane conversion factor of untreated wastewater that is discharged into river, lake and sea | S7: CH4 | T7: 0.1
B8: 4 | C8: Natural Gas | D8: tons/mil. m3 | F8: 862 | G8: PVN, GPP Southeast region | J8: Sulfur hexafluoride | K8: SF6 | L8: 25200 | R8: N2O emission factor (Kg N2O-N/kg-N) | S8: N2O | T8: 0.01
B9: 5 | C9: Natural Gas | D9: kg/m3 | F9: 0.862 | G9: PVN, GPP Southeast region | J9: Nitrogen trichloride | K9: NF3 | L9: 17400
B10: 6 | C10: LPG | D10: kg/m3 | E10: 522.2 | F10: 522.2 | G10: IEA’s Energy Statistics Manual (OECD/IEA, 2004) | H10: Suppose the mixture is 70% propane and 30% butane by mass. | J10: HFC-23 (R-23) | K10: CHF3 | L10: 14600 | R10: Default MCF values for Industrial wastewater
B11: 7 | C11: LPG | D11: Liters/tons | E11: 1915 | F11: 1915 | G11: IEA’s Energy Statistics Manual (OECD/IEA, 2004) | J11: HFC-32 (R-32) | K11: CH2F2 | L11: 771 | S11: CH4 | T11: MCF
B12: 8 | C12: LNG | D12: kg/m3 | E12: 436 | F12: 436 | G12: CNG, PVGas | J12: HFC-134a (R-134a) | K12: C2H2F4 | L12: 1530 | R12: Methane conversion factor of aerobic and concentrated wastewater treatment system | S12: CH4 | T12: 0.3
B13: 9 | C13: Biogas | D13: kg/m3 | E13: 0,9-0,95 | F13: 0.925 | G13: https://tincay.com/khi-biogas-va-dac-tinh-sinh-hoc/ | J13: HFC-227ea (R-227ea) | K13: C3HF7 | L13: 3600 | R13: Methane conversion factor of semi-aerobic treatment system (swallow anaerobic) | S13: CH4 | T13: 0.2
B14: 10 | C14: Crude oil | D14: kg/m3 | E14: 810-845 | F14: 828 | G14: Dung Quat Oil Refinery | H14: Bach Ho Mine, 15 degrees Celsius | J14: HCFC-22 (R-22) | K14: CHClF2 | L14: 1960 | R14: Methane conversion factor of deep anaerobic system | S14: CH4 | T14: 0.8
B15: 11 | C15: Crude oil | D15: kg/m3 | E15: 876 | F15: 876 | G15: Nghi Son Refinery and Petrochemical Plant | H15: Crude oil imports | J15: HCFC-123 (R-123) | K15: C2HCl2F3 | L15: 90.4 | R15: Methane conversion factor of untreated wastewater that is discharged into river, lake and sea | S15: CH4 | T15: 0.1
B16: 12 | C16: … | D16: … | J16: R-410A | K16: R-32/R-125 (50/50) | L16: 2087.5
J17: R-404A | K17: R-125/R-143a/R-134a (44/52/4) | L17: 3921.6
J18: R-407C | K18: R-32/R-125/R-134a (23/25/52) | L18: 1773.85

Sheet S1-Stationary Combustion
B1: Scope 1 - Stationary Combustion
C3: Unit | D3: Energy consumption | P3: Total Consumption | Q3: Energy consumption | T3: CO2 | V3: CH4 | X3: N2O | Z3: CO2e
C4: (tonnes, litres, cubic metres,…) | Q4: A | R4: B | S4: C | T4: D | U4: E | V4: F | W4: G | X4: H | Y4: I | Z4: K
D5: January | E5: February | F5: March | G5: April | H5: May | I5: June | J5: July | K5: August | L5: September | M5: October | N5: November | O5: December | Q5: Consumption | R5: Conversion Factor | S5: Consumption | T5: CO2 Emission Factor | U5: CO2 Emissions | V5: CH4 Emission Factor | W5: CH4 Emissions | X5: N2O Emission Factor | Y5: N2OEmissions | Z5: CO2e Emissions
Q6: Ktonnes | R6: (TJ/Ktonnes) | S6: (TJ) | T6: (kg CO2/TJ) | U6: (tonnes CO2) | V6: (kg CH4/TJ) | W6: (tonnes CH4) | X6: (kg N2O /TJ) | Y6: (tonnes N2O) | Z6: (tonnes CO2e)
S7: C=A*B | U7: E=C*D/106 | W7: G=C*F/106 | Y7: I=C*H/106 | Z7: K=E+G*28+I*273
B8: Liquid fuels
B9: Crude Oil | R9: 42.3 | S9: =IF(Q9=0,"",Q9*R9) | T9: 73300 | U9: =IF(Q9=0,"",S9*T9/1000) | V9: 3 | W9: =IF(Q9=0,"",S9*V9/1000) | X9: 0.6 | Y9: =IF(Q9=0,"",S9*X9/1000)
B10: Orimulsion | R10: 27.5 | S10: =IF(Q10=0,"",Q10*R10) | T10: 77000 | U10: =IF(Q10=0,"",S10*T10/1000) | V10: 3 | W10: =IF(Q10=0,"",S10*V10/1000) | X10: 0.6 | Y10: =IF(Q10=0,"",S10*X10/1000)
B11: Natural Gas Liquids | R11: 44.2 | S11: =IF(Q11=0,"",Q11*R11) | T11: 64200 | U11: =IF(Q11=0,"",S11*T11/1000) | V11: 3 | W11: =IF(Q11=0,"",S11*V11/1000) | X11: 0.6 | Y11: =IF(Q11=0,"",S11*X11/1000)
B12: Motor Gasoline | R12: 44.3 | S12: =IF(Q12=0,"",Q12*R12) | T12: 69300 | U12: =IF(Q12=0,"",S12*T12/1000) | V12: 3 | W12: =IF(Q12=0,"",S12*V12/1000) | X12: 0.6 | Y12: =IF(Q12=0,"",S12*X12/1000)
B13: Aviation Gasoline | R13: 44.3 | S13: =IF(Q13=0,"",Q13*R13) | T13: 70000 | U13: =IF(Q13=0,"",S13*T13/1000) | V13: 3 | W13: =IF(Q13=0,"",S13*V13/1000) | X13: 0.6 | Y13: =IF(Q13=0,"",S13*X13/1000)
B14: Jet Gasoline | R14: 44.3 | S14: =IF(Q14=0,"",Q14*R14) | T14: 70000 | U14: =IF(Q14=0,"",S14*T14/1000) | V14: 3 | W14: =IF(Q14=0,"",S14*V14/1000) | X14: 0.6 | Y14: =IF(Q14=0,"",S14*X14/1000)
B15: Jet Kerosene | R15: 44.1 | S15: =IF(Q15=0,"",Q15*R15) | T15: 71500 | U15: =IF(Q15=0,"",S15*T15/1000) | V15: 3 | W15: =IF(Q15=0,"",S15*V15/1000) | X15: 0.6 | Y15: =IF(Q15=0,"",S15*X15/1000)
B16: Other Kerosene | R16: 43.8 | S16: =IF(Q16=0,"",Q16*R16) | T16: 71900 | U16: =IF(Q16=0,"",S16*T16/1000) | V16: 3 | W16: =IF(Q16=0,"",S16*V16/1000) | X16: 0.6 | Y16: =IF(Q16=0,"",S16*X16/1000)
B17: Shale Oil | R17: 38.1 | S17: =IF(Q17=0,"",Q17*R17) | T17: 73300 | U17: =IF(Q17=0,"",S17*T17/1000) | V17: 3 | W17: =IF(Q17=0,"",S17*V17/1000) | X17: 0.6 | Y17: =IF(Q17=0,"",S17*X17/1000)
B18: Gas / Diesel Oil | C18: tonnes | D18: 54.67 | E18: 166.19 | F18: 246.81 | G18: 118.44 | H18: 20 | I18: 110.39 | J18: 118.71 | K18: 103.89 | L18: 80.62 | M18: 217.18 | N18: 137.73 | O18: 264.13 | P18: =SUM(D18:O18) -> 1638.76 | Q18: =P18/1000 -> 1.63876 | R18: 43 | S18: =IF(Q18=0,"",Q18*R18) -> 70.46668 | T18: 74100 | U18: =IF(Q18=0,"",S18*T18/1000) -> 5221.581 | V18: 3 | W18: =IF(Q18=0,"",S18*V18/1000) -> 0.21140004 | X18: 0.6 | Y18: =IF(Q18=0,"",S18*X18/1000) -> 0.042280008 | Z18: =U18+W18*28+Y18*273 -> 5239.0426
B19: Residual Fuel Oil | R19: 40.4 | S19: =IF(Q19=0,"",Q19*R19) | T19: 77400 | U19: =IF(Q19=0,"",S19*T19/1000) | V19: 3 | W19: =IF(Q19=0,"",S19*V19/1000) | X19: 0.6 | Y19: =IF(Q19=0,"",S19*X19/1000)
B20: LPG | C20: kg | D20: 52 | E20: 130 | F20: 52 | G20: 52 | H20: 52 | I20: 52 | J20: 52 | K20: 52 | L20: 52 | M20: 130 | N20: 65 | O20: 65 | P20: =SUM(D20:O20) -> 806 | Q20: =P20/1000000 -> 0.000806 | R20: 47.3 | S20: =IF(Q20=0,"",Q20*R20) -> 0.0381238 | T20: 63100 | U20: =IF(Q20=0,"",S20*T20/1000) -> 2.4056118 | V20: 1 | W20: =IF(Q20=0,"",S20*V20/1000) -> 3.81238e-05 | X20: 0.1 | Y20: =IF(Q20=0,"",S20*X20/1000) -> 3.81238e-06 | Z20: =U20+W20*28+Y20*273 -> 2.40772
B21: Ethane | R21: 46.4 | S21: =IF(Q21=0,"",Q21*R21) | T21: 61600 | U21: =IF(Q21=0,"",S21*T21/1000) | V21: 1 | W21: =IF(Q21=0,"",S21*V21/1000) | X21: 0.1 | Y21: =IF(Q21=0,"",S21*X21/1000)
B22: Naphtha | R22: 44.5 | S22: =IF(Q22=0,"",Q22*R22) | T22: 73300 | U22: =IF(Q22=0,"",S22*T22/1000) | V22: 3 | W22: =IF(Q22=0,"",S22*V22/1000) | X22: 0.6 | Y22: =IF(Q22=0,"",S22*X22/1000)
B23: Bitumen | R23: 40.2 | S23: =IF(Q23=0,"",Q23*R23) | T23: 80700 | U23: =IF(Q23=0,"",S23*T23/1000) | V23: 3 | W23: =IF(Q23=0,"",S23*V23/1000) | X23: 0.6 | Y23: =IF(Q23=0,"",S23*X23/1000)
B24: Lubricants | R24: 40.2 | S24: =IF(Q24=0,"",Q24*R24) | T24: 73300 | U24: =IF(Q24=0,"",S24*T24/1000) | V24: 3 | W24: =IF(Q24=0,"",S24*V24/1000) | X24: 0.6 | Y24: =IF(Q24=0,"",S24*X24/1000)
B25: Petroleum Coke | R25: 32.5 | S25: =IF(Q25=0,"",Q25*R25) | T25: 97500 | U25: =IF(Q25=0,"",S25*T25/1000) | V25: 3 | W25: =IF(Q25=0,"",S25*V25/1000) | X25: 0.6 | Y25: =IF(Q25=0,"",S25*X25/1000)
B26: Refinery Feedstocks | R26: 43 | S26: =IF(Q26=0,"",Q26*R26) | T26: 73300 | U26: =IF(Q26=0,"",S26*T26/1000) | V26: 3 | W26: =IF(Q26=0,"",S26*V26/1000) | X26: 0.6 | Y26: =IF(Q26=0,"",S26*X26/1000)
B27: Refinery Gas | R27: 49.5 | S27: =IF(Q27=0,"",Q27*R27) | T27: 57600 | U27: =IF(Q27=0,"",S27*T27/1000) | V27: 1 | W27: =IF(Q27=0,"",S27*V27/1000) | X27: 0.1 | Y27: =IF(Q27=0,"",S27*X27/1000)
B28: Paraffin Waxes | R28: 40.2 | S28: =IF(Q28=0,"",Q28*R28) | T28: 73300 | U28: =IF(Q28=0,"",S28*T28/1000) | V28: 3 | W28: =IF(Q28=0,"",S28*V28/1000) | X28: 0.6 | Y28: =IF(Q28=0,"",S28*X28/1000)
B29: Other Petroleum Products | S29: =IF(Q29=0,"",Q29*R29) | T29: 73300 | U29: =IF(Q29=0,"",S29*T29/1000) | V29: 3 | W29: =IF(Q29=0,"",S29*V29/1000) | X29: 0.6 | Y29: =IF(Q29=0,"",S29*X29/1000) | Z29: =IF(R29=0,"",T29*Y29/10^6)
B30: Solid fuels
B31: Anthracite | R31: 26.7 | S31: =IF(Q31=0,"",Q31*R31) | T31: 98300 | U31: =IF(Q31=0,"",S31*T31/1000) | V31: 1 | W31: =IF(Q31=0,"",S31*V31/1000) | X31: 1.5 | Y31: =IF(Q31=0,"",S31*X31/1000)
B32: Coking Coal | R32: 28.2 | S32: =IF(Q32=0,"",Q32*R32) | T32: 94600 | U32: =IF(Q32=0,"",S32*T32/1000) | V32: 1 | W32: =IF(Q32=0,"",S32*V32/1000) | X32: 1.5 | Y32: =IF(Q32=0,"",S32*X32/1000)
B33: Other Bituminous Coal | R33: 28.2 | S33: =IF(Q33=0,"",Q33*R33) | T33: 94600 | U33: =IF(Q33=0,"",S33*T33/1000) | V33: 1 | W33: =IF(Q33=0,"",S33*V33/1000) | X33: 1.5 | Y33: =IF(Q33=0,"",S33*X33/1000)
B34: Sub-bituminous coal | C34: tonnes | D34: 414167 | E34: 290945 | F34: 371099 | G34: 398417 | H34: 444814 | I34: 322436 | J34: 337317 | K34: 288514 | L34: 166038.2 | M34: 266070.58 | N34: 381556 | O34: 327877 | P34: =SUM(D34:O34) -> 4009250.8 | Q34: =P34/1000 -> 4009.2508 | R34: 18.9 | S34: =IF(Q34=0,"",Q34*R34) -> 75774.84 | T34: 96100 | U34: =IF(Q34=0,"",S34*T34/1000) -> 7281962.1 | V34: 1 | W34: =IF(Q34=0,"",S34*V34/1000) -> 75.77484 | X34: 1.5 | Y34: =IF(Q34=0,"",S34*X34/1000) -> 113.66226 | Z34: =U34+W34*28+Y34*273 -> 7315113.6
B35: Lignite | R35: 11.9 | S35: =IF(Q35=0,"",Q35*R35) | T35: 101000 | U35: =IF(Q35=0,"",S35*T35/1000) | V35: 1 | W35: =IF(Q35=0,"",S35*V35/1000) | X35: 1.5 | Y35: =IF(Q35=0,"",S35*X35/1000)
B36: Oil Shale and Tar Sands | R36: 8.9 | S36: =IF(Q36=0,"",Q36*R36) | T36: 107000 | U36: =IF(Q36=0,"",S36*T36/1000) | V36: 1 | W36: =IF(Q36=0,"",S36*V36/1000) | X36: 1.5 | Y36: =IF(Q36=0,"",S36*X36/1000)
B37: Brown Coal Briquettes | R37: 20.7 | S37: =IF(Q37=0,"",Q37*R37) | T37: 97500 | U37: =IF(Q37=0,"",S37*T37/1000) | V37: 1 | W37: =IF(Q37=0,"",S37*V37/1000) | X37: 1.5 | Y37: =IF(Q37=0,"",S37*X37/1000)
B38: Patent Fuel | R38: 20.7 | S38: =IF(Q38=0,"",Q38*R38) | T38: 97500 | U38: =IF(Q38=0,"",S38*T38/1000) | V38: 1 | W38: =IF(Q38=0,"",S38*V38/1000) | X38: 1.5 | Y38: =IF(Q38=0,"",S38*X38/1000)
B39: Coke Oven Coke / Lignite Coke | R39: 28.2 | S39: =IF(Q39=0,"",Q39*R39) | T39: 107000 | U39: =IF(Q39=0,"",S39*T39/1000) | V39: 1 | W39: =IF(Q39=0,"",S39*V39/1000) | X39: 1.5 | Y39: =IF(Q39=0,"",S39*X39/1000)
B40: Gas Coke | R40: 28.2 | S40: =IF(Q40=0,"",Q40*R40) | T40: 107000 | U40: =IF(Q40=0,"",S40*T40/1000) | V40: 1 | W40: =IF(Q40=0,"",S40*V40/1000) | X40: 0.1 | Y40: =IF(Q40=0,"",S40*X40/1000)
B41: Coal Tar | R41: 28 | S41: =IF(Q41=0,"",Q41*R41) | T41: 80700 | U41: =IF(Q41=0,"",S41*T41/1000) | V41: 1 | W41: =IF(Q41=0,"",S41*V41/1000) | X41: 1.5 | Y41: =IF(Q41=0,"",S41*X41/1000)
...

Sheet S1-Mobile Combustion
B1: Scope 1 - Mobile Combustion
C3: Unit | D3: Energy consumption | P3: Total Consumption | Q3: Energy consumption | T3: CO2 | V3: CH4 | X3: N2O | Z3: CO2e
C4: (tonnes, litres, cubic metres,…) | Q4: A | R4: B | S4: C | T4: D | U4: E | V4: F | W4: G | X4: H | Y4: I | Z4: K
D5: January | E5: February | F5: March | G5: April | H5: May | I5: June | J5: July | K5: August | L5: September | M5: October | N5: November | O5: December | Q5: Consumption | R5: Conversion Factor | S5: Consumption | T5: CO2 Emission Factor | U5: CO2 Emissions | V5: CH4 Emission Factor | W5: CH4 Emissions | X5: N2O Emission Factor | Y5: N2OEmissions | Z5: CO2e Emissions
Q6: Ktonnes | R6: (TJ/Ktonnes) | S6: (TJ) | T6: (kg CO2/TJ) | U6: (tonnes CO2) | V6: (kg CH4/TJ) | W6: (tonnes CH4) | X6: (kg N2O /TJ) | Y6: (tonnes N2O) | Z6: (tonnes CO2e)
S7: C=A*B | U7: E=C*D/106 | W7: G=C*F/106 | Y7: I=C*H/106 | Z7: K=E+G*28+I*273
B8: Liquid fuels
B9: Crude Oil | R9: 42.3 | S9: =IF(Q9=0,"",Q9*R9) | T9: 73300 | U9: =IF(Q9=0,"",S9*T9/1000) | W9: =IF(Q9=0,"",S9*V9/1000) | Y9: =IF(Q9=0,"",S9*X9/1000)
B10: Orimulsion | R10: 27.5 | S10: =IF(Q10=0,"",Q10*R10) | T10: 77000 | U10: =IF(Q10=0,"",S10*T10/1000) | W10: =IF(Q10=0,"",S10*V10/1000) | Y10: =IF(Q10=0,"",S10*X10/1000)
B11: Natural Gas Liquids | R11: 44.2 | S11: =IF(Q11=0,"",Q11*R11) | T11: 64200 | U11: =IF(Q11=0,"",S11*T11/1000) | W11: =IF(Q11=0,"",S11*V11/1000) | Y11: =IF(Q11=0,"",S11*X11/1000)
B12: Motor Gasoline | C12: Litres | F12: 62.47 | H12: 68 | J12: 62 | L12: 113 | N12: 62 | O12: 57.44 | P12: =SUM(D12:O12) -> 424.91 | Q12: =$P$12*'Conversion Factors'!$F$7/1000000 -> 0.000339928 | R12: 44.3 | S12: =IF(Q12=0,"",Q12*R12) -> 0.01505881 | T12: 69300 | U12: =IF(Q12=0,"",S12*T12/1000) -> 1.0435756 | V12: 33 | W12: =IF(Q12=0,"",S12*V12/1000) -> 0.00049694074 | X12: 3.2 | Y12: =IF(Q12=0,"",S12*X12/1000) -> 4.8188193e-05 | Z12: =U12+W12*28+Y12*273 -> 1.0706453
B13: Aviation Gasoline | R13: 44.3 | S13: =IF(Q13=0,"",Q13*R13) | T13: 70000 | U13: =IF(Q13=0,"",S13*T13/1000) | W13: =IF(Q13=0,"",S13*V13/1000) | Y13: =IF(Q13=0,"",S13*X13/1000)
B14: Jet Gasoline | R14: 44.3 | S14: =IF(Q14=0,"",Q14*R14) | T14: 70000 | U14: =IF(Q14=0,"",S14*T14/1000) | W14: =IF(Q14=0,"",S14*V14/1000) | Y14: =IF(Q14=0,"",S14*X14/1000)
B15: Jet Kerosene | R15: 44.1 | S15: =IF(Q15=0,"",Q15*R15) | T15: 71500 | U15: =IF(Q15=0,"",S15*T15/1000) | W15: =IF(Q15=0,"",S15*V15/1000) | Y15: =IF(Q15=0,"",S15*X15/1000)
B16: Other Kerosene | R16: 43.8 | S16: =IF(Q16=0,"",Q16*R16) | T16: 71900 | U16: =IF(Q16=0,"",S16*T16/1000) | W16: =IF(Q16=0,"",S16*V16/1000) | Y16: =IF(Q16=0,"",S16*X16/1000)
B17: Shale Oil | R17: 38.1 | S17: =IF(Q17=0,"",Q17*R17) | T17: 73300 | U17: =IF(Q17=0,"",S17*T17/1000) | W17: =IF(Q17=0,"",S17*V17/1000) | Y17: =IF(Q17=0,"",S17*X17/1000)
B18: Gas / Diesel Oil | C18: Litres | D18: 12438 | E18: 7686 | F18: 11523 | G18: 10915 | H18: 13703 | I18: 20339 | J18: 32592 | K18: 21896 | L18: 13801 | M18: 12627 | N18: 31596 | O18: 3230 | P18: =SUM(D18:O18) -> 192346 | Q18: =$P$18*'Conversion Factors'!$F$5/1000000 -> 0.16541756 | R18: 43 | S18: =IF(Q18=0,"",Q18*R18) -> 7.1129551 | T18: 74100 | U18: =IF(Q18=0,"",S18*T18/1000) -> 527.06997 | V18: 3.9 | W18: =IF(Q18=0,"",S18*V18/1000) -> 0.027740525 | X18: 3.9 | Y18: =IF(Q18=0,"",S18*X18/1000) -> 0.027740525 | Z18: =U18+W18*28+Y18*273 -> 535.41987
B19: Residual Fuel Oil | R19: 40.4 | S19: =IF(Q19=0,"",Q19*R19) | T19: 77400 | U19: =IF(Q19=0,"",S19*T19/1000) | W19: =IF(Q19=0,"",S19*V19/1000) | Y19: =IF(Q19=0,"",S19*X19/1000)
B20: LPG | R20: 47.3 | S20: =IF(Q20=0,"",Q20*R20) | T20: 63100 | U20: =IF(Q20=0,"",S20*T20/1000) | W20: =IF(Q20=0,"",S20*V20/1000) | Y20: =IF(Q20=0,"",S20*X20/1000)
B21: Ethane | R21: 46.4 | S21: =IF(Q21=0,"",Q21*R21) | T21: 61600 | U21: =IF(Q21=0,"",S21*T21/1000) | W21: =IF(Q21=0,"",S21*V21/1000) | Y21: =IF(Q21=0,"",S21*X21/1000)
B22: Naphtha | R22: 44.5 | S22: =IF(Q22=0,"",Q22*R22) | T22: 73300 | U22: =IF(Q22=0,"",S22*T22/1000) | W22: =IF(Q22=0,"",S22*V22/1000) | Y22: =IF(Q22=0,"",S22*X22/1000)
B23: Bitumen | R23: 40.2 | S23: =IF(Q23=0,"",Q23*R23) | T23: 80700 | U23: =IF(Q23=0,"",S23*T23/1000) | W23: =IF(Q23=0,"",S23*V23/1000) | Y23: =IF(Q23=0,"",S23*X23/1000)
B24: Lubricants | R24: 40.2 | S24: =IF(Q24=0,"",Q24*R24) | T24: 73300 | U24: =IF(Q24=0,"",S24*T24/1000) | W24: =IF(Q24=0,"",S24*V24/1000) | Y24: =IF(Q24=0,"",S24*X24/1000)
B25: Petroleum Coke | R25: 32.5 | S25: =IF(Q25=0,"",Q25*R25) | T25: 97500 | U25: =IF(Q25=0,"",S25*T25/1000) | W25: =IF(Q25=0,"",S25*V25/1000) | Y25: =IF(Q25=0,"",S25*X25/1000)
B26: Refinery Feedstocks | R26: 43 | S26: =IF(Q26=0,"",Q26*R26) | T26: 73300 | U26: =IF(Q26=0,"",S26*T26/1000) | W26: =IF(Q26=0,"",S26*V26/1000) | Y26: =IF(Q26=0,"",S26*X26/1000)
B27: Refinery Gas | R27: 49.5 | S27: =IF(Q27=0,"",Q27*R27) | T27: 57600 | U27: =IF(Q27=0,"",S27*T27/1000) | W27: =IF(Q27=0,"",S27*V27/1000) | Y27: =IF(Q27=0,"",S27*X27/1000)
B28: Paraffin Waxes | R28: 40.2 | S28: =IF(Q28=0,"",Q28*R28) | T28: 73300 | U28: =IF(Q28=0,"",S28*T28/1000) | W28: =IF(Q28=0,"",S28*V28/1000) | Y28: =IF(Q28=0,"",S28*X28/1000)
B29: Other Petroleum Products | S29: =IF(Q29=0,"",Q29*R29) | T29: 73300 | U29: =IF(Q29=0,"",S29*T29/1000) | W29: =IF(Q29=0,"",S29*V29/1000) | Y29: =IF(Q29=0,"",S29*X29/1000) | Z29: =IF(R29=0,"",T29*Y29/10^6)
B30: Solid fuels
B31: Anthracite | R31: 26.7 | S31: =IF(Q31=0,"",Q31*R31) | T31: 98300 | U31: =IF(Q31=0,"",S31*T31/1000) | W31: =IF(Q31=0,"",S31*V31/1000) | Y31: =IF(Q31=0,"",S31*X31/1000)
B32: Coking Coal | R32: 28.2 | S32: =IF(Q32=0,"",Q32*R32) | T32: 94600 | U32: =IF(Q32=0,"",S32*T32/1000) | W32: =IF(Q32=0,"",S32*V32/1000) | Y32: =IF(Q32=0,"",S32*X32/1000)
B33: Other Bituminous Coal | R33: 28.2 | S33: =IF(Q33=0,"",Q33*R33) | T33: 94600 | U33: =IF(Q33=0,"",S33*T33/1000) | W33: =IF(Q33=0,"",S33*V33/1000) | Y33: =IF(Q33=0,"",S33*X33/1000)
B34: Sub-bituminous coal | D34: 414167 | E34: 290945 | F34: 371099 | G34: 398417 | H34: 444814 | I34: 322436 | J34: 337317 | K34: 288514 | L34: 166038.2 | M34: 266070.58 | N34: 381556 | R34: 18.9 | S34: =IF(Q34=0,"",Q34*R34) | T34: 96100 | U34: =IF(Q34=0,"",S34*T34/1000) | W34: =IF(Q34=0,"",S34*V34/1000) | Y34: =IF(Q34=0,"",S34*X34/1000)
B35: Lignite | R35: 11.9 | S35: =IF(Q35=0,"",Q35*R35) | T35: 101000 | U35: =IF(Q35=0,"",S35*T35/1000) | W35: =IF(Q35=0,"",S35*V35/1000) | Y35: =IF(Q35=0,"",S35*X35/1000)
B36: Oil Shale and Tar Sands | R36: 8.9 | S36: =IF(Q36=0,"",Q36*R36) | T36: 107000 | U36: =IF(Q36=0,"",S36*T36/1000) | W36: =IF(Q36=0,"",S36*V36/1000) | Y36: =IF(Q36=0,"",S36*X36/1000)
B37: Brown Coal Briquettes | R37: 20.7 | S37: =IF(Q37=0,"",Q37*R37) | T37: 97500 | U37: =IF(Q37=0,"",S37*T37/1000) | W37: =IF(Q37=0,"",S37*V37/1000) | Y37: =IF(Q37=0,"",S37*X37/1000)
B38: Patent Fuel | R38: 20.7 | S38: =IF(Q38=0,"",Q38*R38) | T38: 97500 | U38: =IF(Q38=0,"",S38*T38/1000) | W38: =IF(Q38=0,"",S38*V38/1000) | Y38: =IF(Q38=0,"",S38*X38/1000)
B39: Coke Oven Coke / Lignite Coke | R39: 28.2 | S39: =IF(Q39=0,"",Q39*R39) | T39: 107000 | U39: =IF(Q39=0,"",S39*T39/1000) | W39: =IF(Q39=0,"",S39*V39/1000) | Y39: =IF(Q39=0,"",S39*X39/1000)
B40: Gas Coke | R40: 28.2 | S40: =IF(Q40=0,"",Q40*R40) | T40: 107000 | U40: =IF(Q40=0,"",S40*T40/1000) | W40: =IF(Q40=0,"",S40*V40/1000) | Y40: =IF(Q40=0,"",S40*X40/1000)
B41: Coal Tar | R41: 28 | S41: =IF(Q41=0,"",Q41*R41) | T41: 80700 | U41: =IF(Q41=0,"",S41*T41/1000) | W41: =IF(Q41=0,"",S41*V41/1000) | Y41: =IF(Q41=0,"",S41*X41/1000)
...

Sheet S1-Refrigerants
B1: Scope 1 - Refrigerants Use
B3: A | D3: B | E3: Amount of refrigerant charged 2020 | Q3: C | R3: D | S3: E
B4: Refrigerant type | C4: Unit | D4: GWP of the Refrigerant | E4: January | F4: February | G4: March | H4: April | I4: May | J4: June | K4: July | L4: August | M4: September | N4: October | O4: November | P4: December | Q4: Total annual recharge | R4: Conversion factor | S4: Total emissions
Q5: (kg) | R5: (tonnes/kg) | S5: (tonnes CO2e/year)
S6: E = B * C * D
B7: R-410A | C7: kg | D7: ='Conversion Factors'!L16 -> 2087.5 | E7: 22.7 | F7: 11.35 | G7: 0 | H7: 45.4 | I7: 0 | J7: 45.4 | K7: 45.4 | L7: 0 | M7: 34.05 | N7: 0 | O7: 0 | Q7: =SUM(E7:P7) -> 204.3 | R7: 0.001 | S7: =D7*Q7*R7 -> 426.47625
B8: R-410A (Chemours) | C8: kg | D8: =D7 -> 2087.5 | E8: 0 | F8: 0 | G8: 0 | H8: 0 | I8: 45.4 | J8: 0 | K8: 0 | L8: 0 | M8: 0 | N8: 0 | O8: 0 | Q8: =SUM(E8:P8) -> 45.4 | R8: 0.001 | S8: =D8*Q8*R8 -> 94.7725
B9: R-407C | C9: kg | D9: ='Conversion Factors'!L18 -> 1773.85 | E9: 0 | F9: 11.35 | G9: 0 | H9: 0 | I9: 0 | J9: 0 | K9: 0 | L9: 34.05 | M9: 0 | N9: 22.7 | O9: 0 | Q9: =SUM(E9:P9) -> 68.1 | R9: 0.001 | S9: =D9*Q9*R9 -> 120.79918
B10: Total | S10: =SUM(S7:S9) -> 642.04794

Sheet S1-Industrial processes
B1: Scope 1 - Industrial processes
B3: AD from industrial processes 2024 | P3: A | Q3: B | R3: C
B4: Product name/fuel used | C4: Unit | D4: January | E4: February | F4: March | G4: April | H4: May | I4: June | J4: July | K4: August | L4: September | M4: October | N4: November | O4: December | P4: Total Consumption | Q4: CO2 Emission Factor | R4: CO2 Emissions
Q5: (tonnes CO2/tonne carbonate) | R5: (tonnes CO2e/year)
R6: C = A * B
B7: CaCO3 desulfurization (Limestone content 98.33 %) | C7: tonnes | D7: 1503.05 | E7: 990.8 | F7: 1235.86 | G7: 1130.37 | H7: 1394.74 | I7: 773.13 | J7: 862.17 | K7: 1031 | L7: 647.08 | M7: 945.48 | N7: 1134.99 | P7: =SUM(D7:O7) -> 11648.67 | Q7: 0.43971 | R7: =P7*Q7 -> 5122.0367
B8: NH3 gas used to reduce NOx | C8: tonnes | D8: 0.45 | E8: 1.48 | F8: 0.53 | G8: 0.17 | H8: 0.17 | I8: 2.01 | J8: 0.88 | K8: 6.13 | L8: 4.5 | M8: 0.05 | N8: 1.26 | P8: =SUM(D8:O8) -> 17.63 | R8: =P8*Q8 -> 0
B9: N2 gas cleans pipes, runs coal analyzer | C9: litrers | D9: 188 | E9: 188 | F9: 188 | G9: 188 | H9: 188 | I9: 188 | J9: 188 | K9: 188 | L9: 188 | M9: 188 | N9: 188 | P9: =SUM(D9:O9) -> 2068 | R9: =P9*Q9 -> 0
B10: Welding rod | C10: kg | D10: 41.4 | E10: 160 | G10: 40 | H10: 14 | I10: 35 | J10: 20 | K10: 75 | L10: 35 | M10: 91 | N10: 6 | P10: =SUM(D10:O10) -> 517.4 | R10: =P10*Q10 -> 0
B11: Ammonia solution 25% (NH4OH) | C11: kg | D11: 2880 | E11: 3500 | F11: 3240 | G11: 3060 | H11: 5660 | I11: 4140 | J11: 5300 | K11: 4580 | L11: 3510 | M11: 2700 | N11: 5390 | P11: =SUM(D11:O11) -> 43960
B12: Carbohydrazide 99% (CH6N4O) | C12: kg | D12: 83 | E12: 13 | F12: 50 | G12: 50 | H12: 63 | I12: 50 | J12: 75 | K12: 50 | L12: 38 | M12: 0 | N12: 0 | P12: =SUM(D12:O12) -> 472
B13: Hydrazine 80% (N2H4) | C13: kg | D13: 0 | E13: 0 | F13: 0 | G13: 0 | H13: 0 | I13: 0 | J13: 0 | K13: 0 | L13: 0 | M13: 50 | N13: 125 | P13: =SUM(D13:O13) -> 175
B14: EDTA (C10H16N2O8) | C14: kg | D14: 0 | E14: 0 | F14: 0 | G14: 0 | H14: 0 | I14: 0 | J14: 0 | K14: 0 | L14: 137 | M14: 0 | N14: 0 | P14: =SUM(D14:O14) -> 137
B15: Na2CO3 | C15: kg | D15: 42 | E15: 42 | F15: 42 | G15: 42 | H15: 42 | I15: 42 | J15: 42 | K15: 42 | L15: 42 | M15: 42 | N15: 42 | P15: =SUM(D15:O15) -> 462
B16: AXID CITRIC (C6H8O7) | C16: kg | D16: 450 | E16: 350 | F16: 300 | G16: 225 | H16: 400 | I16: 275 | J16: 375 | K16: 475 | L16: 50 | M16: 75 | N16: 125 | P16: =SUM(D16:O16) -> 3100
B17: ANIONIC POLYMER (CONH2[CH2-CH-]n) | C17: kg | D17: 25 | E17: 0 | F17: 100 | G17: 25 | H17: 0 | I17: 25 | J17: 25 | K17: 25 | L17: 50 | M17: 75 | N17: 125 | P17: =SUM(D17:O17) -> 475
B18: Total | R18: =SUM(R7:R17) -> 5122.0367

Sheet S1-Wastewater Treatment
B1: Scope 1 - Wastewater Treatment
B3: Domestic wastewater
B4: 2024 | P4: A | Q4: B | R4: C | S4: D | T4: E | U4: F | V4: G | W4: H | X4: I | Y4: K
B5: Type of treatment or discharge | C5: Unit | D5: January | E5: February | F5: March | G5: April | H5: May | I5: June | J5: July | K5: August | L5: September | M5: October | N5: November | O5: December | P5: Amount of wastewater generated 2024 | Q5: Biochemical oxygen Demand (BOD) | R5: Organically degradable material in wastewater | S5: Maximum methane generation potential | T5: Methane correction factor for treatment system | U5: Emission factor | V5: Sludge is removed | W5: CH4 is recovered in the treatment system | X5: Net methane emissions | Y5: CO2e Emissions
P6: (Wi) | Q6: (BODi) | R6: (TOWi) | S6: (B0) | T6: (MCFj) | U6: (EFj) | V6: (Si) | W6: (Ri) | X6: (CH4)
P7: (m3/year) | Q7: (kgBOD/m3) | R7: (kgBOD/year) | S7: (kg CH4/kg BOD) | T7: ( - ) | U7: (kg CH4/kg BOD) | V7: (kg BOD/year) | W7: (kg CH4/year) | X7: (kg CH4/year) | Y7: tCO2e/year
R8: C = A * B | U8: F = D * E | X8: I = [(C – G) * F] – H | Y8: K = I * 28/1000
C9: m3 | D9: 2380 | E9: 2311 | F9: 2470 | G9: 2386 | H9: 2474 | I9: 2391 | J9: 2477 | K9: 2470 | L9: 2394 | M9: 2472 | N9: 2388 | O9: 1447 | P9: =SUM(D9:O9) -> 28060 | Q9: =AVERAGE(14,20,8,12)/1000 -> 0.0135 | R9: =P9*Q9 -> 378.81 | S9: 0.6 | T9: 0.3 | U9: =S9*T9 -> 0.18 | V9: 0 | W9: 0 | X9: =((R9-V9)*U9)-W9 -> 68.1858 | Y9: =X9*28/1000 -> 1.9092024
C10: m3 | R10: =P10*Q10 -> 0 | U10: =S10*T10 -> 0 | V10: 0 | W10: 0 | X10: =((R10-V10)*U10)-W10 -> 0 | Y10: =X10*28/1000 -> 0
C11: m3 | R11: =P11*Q11 -> 0 | U11: =S11*T11 -> 0 | V11: 0 | W11: 0 | X11: =((R11-V11)*U11)-W11 -> 0 | Y11: =X11*28/1000 -> 0
C12: m3 | R12: =P12*Q12 -> 0 | U12: =S12*T12 -> 0 | V12: 0 | W12: 0 | X12: =((R12-V12)*U12)-W12 -> 0 | Y12: =X12*28/1000 -> 0
B13: Total | X13: =SUM(X9:X12) -> 68.1858 | Y13: =SUM(Y9:Y12) -> 1.9092024
B15: Industrial wastewater
B16: 2024 | P16: A | Q16: B | R16: C | S16: D | T16: E | U16: F | V16: G | W16: H | X16: I | Y16: K
B17: Type of treatment or discharge | C17: Unit | D17: January | E17: February | F17: March | G17: April | H17: May | I17: June | J17: July | K17: August | L17: September | M17: October | N17: November | O17: December | P17: Amount of wastewater generated 2024 | Q17: Chemical oxygen demand (COD) | R17: Organically degradable material in wastewater | S17: Maximum methane generation potential | T17: Methane correction factor for treatment system | U17: Emission factor | V17: Sludge is removed | W17: CH4 is recovered in the treatment system | X17: Net methane emissions | Y17: CO2e Emissions
P18: (Wi) | Q18: (CODi) | R18: (TOWi) | S18: (B0) | T18: (MCFj) | U18: (EFj) | V18: (Si) | W18: (Ri) | X18: (CH4)
P19: (m3/year) | Q19: (kgCOD/m3) | R19: (kgCOD/year) | S19: (kg CH4/kg COD) | T19: ( - ) | U19: (kg CH4/kg COD) | V19: (kg COD/year) | W19: (kg CH4/year) | X19: (kg CH4/year) | Y19: tCO2e/year
R20: C = A * B | U20: F = D * E | X20: I = [(C – G) * F] – H | Y20: K = I * 28/1000
C21: m3 | D21: 56916.7 | E21: 50157.61 | F21: 72358.63 | G21: 41598.01 | H21: 38645.24 | I21: 63994.51 | J21: 55355.96 | K21: 40184.03 | L21: 38603.06 | M21: 66251.4 | N21: 44917.5 | O21: 56494.03 | P21: =SUM(D21:O21) -> 625476.68 | Q21: =AVERAGE(51.32,67.95,55.01,53.56,53.64,48.51,58.54,46.76,40.68,36.09,44.76,40.97)/1000 -> 0.049815833 | R21: =P21*Q21 -> 31158.642 | S21: 0.25 | T21: 0.3 | U21: =S21*T21 -> 0.075 | V21: 0 | W21: 0 | X21: =((R21-V21)*U21)-W21 -> 2336.8982 | Y21: =X21*28/1000 -> 65.433148
C22: m3 | R22: =P22*Q22 -> 0 | U22: =S22*T22 -> 0 | V22: 0 | W22: 0 | X22: =((R22-V22)*U22)-W22 -> 0 | Y22: =X22*28/1000 -> 0
R23: =P23*Q23 -> 0 | U23: =S23*T23 -> 0 | V23: 0 | W23: 0 | X23: =((R23-V23)*U23)-W23 -> 0 | Y23: =X23*28/1000 -> 0
R24: =P24*Q24 -> 0 | U24: =S24*T24 -> 0 | V24: 0 | W24: 0 | X24: =((R24-V24)*U24)-W24 -> 0 | Y24: =X24*28/1000 -> 0
B25: Total | X25: =SUM(X21:X24) -> 2336.8982 | Y25: =SUM(Y21:Y24) -> 65.433148

Sheet S2-Electricity Consumption
B1: Scope 2 - Electricity Consumption
B3: A | D3: B | E3: C | F3: D
B4: Month | C4: Amount of electricity purchased from the national grid in 2024 | D4: Conversion factor | E4: Grid Emissions Factor 2023 | F4: CO2 Emission
C5: kWh | D5: kWh/MWh | E5: tCO2/MWh | F5: (tonnes)
F6: D = A * B * C
B7: January | C7: 43020 | D7: 0.001 | E7: 0.6592 | F7: =C7*D7*E7 -> 28.358784
B8: February | C8: 1408240 | D8: 0.001 | E8: 0.6592 | F8: =C8*D8*E8 -> 928.31181
B9: March | C9: 851425 | D9: 0.001 | E9: 0.6592 | F9: =C9*D9*E9 -> 561.25936
B10: April | C10: 584968 | D10: 0.001 | E10: 0.6592 | F10: =C10*D10*E10 -> 385.61091
B11: May | C11: 53178 | D11: 0.001 | E11: 0.6592 | F11: =C11*D11*E11 -> 35.054938
B12: June | C12: 59553 | D12: 0.001 | E12: 0.6592 | F12: =C12*D12*E12 -> 39.257338
B13: July | C13: 60720 | D13: 0.001 | E13: 0.6592 | F13: =C13*D13*E13 -> 40.026624
B14: August | C14: 61380 | D14: 0.001 | E14: 0.6592 | F14: =C14*D14*E14 -> 40.461696
B15: September | C15: 522600 | D15: 0.001 | E15: 0.6592 | F15: =C15*D15*E15 -> 344.49792
B16: October | C16: 1262790 | D16: 0.001 | E16: 0.6592 | F16: =C16*D16*E16 -> 832.43117
B17: November | C17: 42238 | D17: 0.001 | E17: 0.6592 | F17: =C17*D17*E17 -> 27.84329
B18: December | C18: 2147600 | D18: 0.001 | E18: 0.6592 | F18: =C18*D18*E18 -> 1415.6979
C19: =SUM(C7:C18) -> 7097712 | E19: Total | F19: =SUM(F7:F18) -> 4678.8117
